Mon May 25 17:12:23 CEST 2020 : Apache Derby Network Server - 10.14.2.0 - (1828579) started and ready to accept connections on port 1527
----------------------------------------------------------------
Mon May 25 17:12:24 CEST 2020:
Booting Derby version The Apache Software Foundation - Apache Derby - 10.14.2.0 - (1828579): instance a816c00e-0172-4c64-5584-ffffbbcdf971 
on database directory C:\Users\Moritz Weibold\OneDrive - HTBLA Leonding\ITP\Projekt\Trainity\Projekt_Code\DB\TrainityDB with class loader sun.misc.Launcher$AppClassLoader@1d44bcfa 
Loaded from file:/C:/Users/Moritz%20Weibold/OneDrive%20-%20HTBLA%20Leonding/SEW/Libraries/db-derby-10.14.2.0-lib/lib/derby.jar
java.vendor=Oracle Corporation
java.runtime.version=1.8.0_231-b11
user.dir=C:\Users\Moritz Weibold\OneDrive - HTBLA Leonding\SEW\Libraries\db-derby-10.14.2.0-lib
os.name=Windows 10
os.arch=amd64
os.version=10.0
derby.system.home=C:\Users\Moritz Weibold\OneDrive - HTBLA Leonding\ITP\Projekt\Trainity\Projekt_Code\DB
Database Class Loader started - derby.database.classpath=''
Mon May 25 17:12:27 CEST 2020 Thread[DRDAConnThread_2,5,main] (XID = 1054), (SESSIONID = 0), (DATABASE = TrainityDB), (DRDAID = {1}), Cleanup action starting
java.sql.SQLNonTransientConnectionException: Connection authentication failure occurred.  Reason: Invalid authentication..
	at org.apache.derby.impl.jdbc.SQLExceptionFactory.getSQLException(Unknown Source)
	at org.apache.derby.impl.jdbc.SQLExceptionFactory.getSQLException(Unknown Source)
	at org.apache.derby.impl.jdbc.Util.generateCsSQLException(Unknown Source)
	at org.apache.derby.impl.jdbc.Util.generateCsSQLException(Unknown Source)
	at org.apache.derby.impl.jdbc.EmbedConnection.newSQLException(Unknown Source)
	at org.apache.derby.impl.jdbc.EmbedConnection.checkUserCredentials(Unknown Source)
	at org.apache.derby.impl.jdbc.EmbedConnection.<init>(Unknown Source)
	at org.apache.derby.jdbc.InternalDriver$1.run(Unknown Source)
	at org.apache.derby.jdbc.InternalDriver$1.run(Unknown Source)
	at java.security.AccessController.doPrivileged(Native Method)
	at org.apache.derby.jdbc.InternalDriver.getNewEmbedConnection(Unknown Source)
	at org.apache.derby.jdbc.InternalDriver.connect(Unknown Source)
	at org.apache.derby.jdbc.InternalDriver.connect(Unknown Source)
	at org.apache.derby.jdbc.EmbeddedDriver.connect(Unknown Source)
	at org.apache.derby.impl.drda.Database.makeConnection(Unknown Source)
	at org.apache.derby.impl.drda.DRDAConnThread.getConnFromDatabaseName(Unknown Source)
	at org.apache.derby.impl.drda.DRDAConnThread.verifyUserIdPassword(Unknown Source)
	at org.apache.derby.impl.drda.DRDAConnThread.parseSECCHK(Unknown Source)
	at org.apache.derby.impl.drda.DRDAConnThread.parseDRDAConnection(Unknown Source)
	at org.apache.derby.impl.drda.DRDAConnThread.processCommands(Unknown Source)
	at org.apache.derby.impl.drda.DRDAConnThread.run(Unknown Source)
Caused by: ERROR 08004: Connection authentication failure occurred.  Reason: Invalid authentication..
	at org.apache.derby.iapi.error.StandardException.newException(Unknown Source)
	at org.apache.derby.impl.jdbc.SQLExceptionFactory.wrapArgsForTransportAcrossDRDA(Unknown Source)
	... 21 more
============= begin nested exception, level (1) ===========
ERROR 08004: Connection authentication failure occurred.  Reason: Invalid authentication..
	at org.apache.derby.iapi.error.StandardException.newException(Unknown Source)
	at org.apache.derby.impl.jdbc.SQLExceptionFactory.wrapArgsForTransportAcrossDRDA(Unknown Source)
	at org.apache.derby.impl.jdbc.SQLExceptionFactory.getSQLException(Unknown Source)
	at org.apache.derby.impl.jdbc.SQLExceptionFactory.getSQLException(Unknown Source)
	at org.apache.derby.impl.jdbc.Util.generateCsSQLException(Unknown Source)
	at org.apache.derby.impl.jdbc.Util.generateCsSQLException(Unknown Source)
	at org.apache.derby.impl.jdbc.EmbedConnection.newSQLException(Unknown Source)
	at org.apache.derby.impl.jdbc.EmbedConnection.checkUserCredentials(Unknown Source)
	at org.apache.derby.impl.jdbc.EmbedConnection.<init>(Unknown Source)
	at org.apache.derby.jdbc.InternalDriver$1.run(Unknown Source)
	at org.apache.derby.jdbc.InternalDriver$1.run(Unknown Source)
	at java.security.AccessController.doPrivileged(Native Method)
	at org.apache.derby.jdbc.InternalDriver.getNewEmbedConnection(Unknown Source)
	at org.apache.derby.jdbc.InternalDriver.connect(Unknown Source)
	at org.apache.derby.jdbc.InternalDriver.connect(Unknown Source)
	at org.apache.derby.jdbc.EmbeddedDriver.connect(Unknown Source)
	at org.apache.derby.impl.drda.Database.makeConnection(Unknown Source)
	at org.apache.derby.impl.drda.DRDAConnThread.getConnFromDatabaseName(Unknown Source)
	at org.apache.derby.impl.drda.DRDAConnThread.verifyUserIdPassword(Unknown Source)
	at org.apache.derby.impl.drda.DRDAConnThread.parseSECCHK(Unknown Source)
	at org.apache.derby.impl.drda.DRDAConnThread.parseDRDAConnection(Unknown Source)
	at org.apache.derby.impl.drda.DRDAConnThread.processCommands(Unknown Source)
	at org.apache.derby.impl.drda.DRDAConnThread.run(Unknown Source)
============= end nested exception, level (1) ===========
Cleanup action completed
Mon May 25 17:12:27 CEST 2020 Thread[DRDAConnThread_2,5,main] (DATABASE = TrainityDB), (DRDAID = {1}), Connection authentication failure occurred.  Reason: Invalid authentication..
Mon May 25 17:12:31 CEST 2020 Thread[DRDAConnThread_2,5,main] (XID = 1055), (SESSIONID = 1), (DATABASE = TrainityDB), (DRDAID = {2}), Cleanup action starting
java.sql.SQLNonTransientConnectionException: Connection authentication failure occurred.  Reason: Invalid authentication..
	at org.apache.derby.impl.jdbc.SQLExceptionFactory.getSQLException(Unknown Source)
	at org.apache.derby.impl.jdbc.SQLExceptionFactory.getSQLException(Unknown Source)
	at org.apache.derby.impl.jdbc.Util.generateCsSQLException(Unknown Source)
	at org.apache.derby.impl.jdbc.Util.generateCsSQLException(Unknown Source)
	at org.apache.derby.impl.jdbc.EmbedConnection.newSQLException(Unknown Source)
	at org.apache.derby.impl.jdbc.EmbedConnection.checkUserCredentials(Unknown Source)
	at org.apache.derby.impl.jdbc.EmbedConnection.<init>(Unknown Source)
	at org.apache.derby.jdbc.InternalDriver$1.run(Unknown Source)
	at org.apache.derby.jdbc.InternalDriver$1.run(Unknown Source)
	at java.security.AccessController.doPrivileged(Native Method)
	at org.apache.derby.jdbc.InternalDriver.getNewEmbedConnection(Unknown Source)
	at org.apache.derby.jdbc.InternalDriver.connect(Unknown Source)
	at org.apache.derby.jdbc.InternalDriver.connect(Unknown Source)
	at org.apache.derby.jdbc.EmbeddedDriver.connect(Unknown Source)
	at org.apache.derby.impl.drda.Database.makeConnection(Unknown Source)
	at org.apache.derby.impl.drda.DRDAConnThread.getConnFromDatabaseName(Unknown Source)
	at org.apache.derby.impl.drda.DRDAConnThread.verifyUserIdPassword(Unknown Source)
	at org.apache.derby.impl.drda.DRDAConnThread.parseSECCHK(Unknown Source)
	at org.apache.derby.impl.drda.DRDAConnThread.parseDRDAConnection(Unknown Source)
	at org.apache.derby.impl.drda.DRDAConnThread.processCommands(Unknown Source)
	at org.apache.derby.impl.drda.DRDAConnThread.run(Unknown Source)
Caused by: ERROR 08004: Connection authentication failure occurred.  Reason: Invalid authentication..
	at org.apache.derby.iapi.error.StandardException.newException(Unknown Source)
	at org.apache.derby.impl.jdbc.SQLExceptionFactory.wrapArgsForTransportAcrossDRDA(Unknown Source)
	... 21 more
============= begin nested exception, level (1) ===========
ERROR 08004: Connection authentication failure occurred.  Reason: Invalid authentication..
	at org.apache.derby.iapi.error.StandardException.newException(Unknown Source)
	at org.apache.derby.impl.jdbc.SQLExceptionFactory.wrapArgsForTransportAcrossDRDA(Unknown Source)
	at org.apache.derby.impl.jdbc.SQLExceptionFactory.getSQLException(Unknown Source)
	at org.apache.derby.impl.jdbc.SQLExceptionFactory.getSQLException(Unknown Source)
	at org.apache.derby.impl.jdbc.Util.generateCsSQLException(Unknown Source)
	at org.apache.derby.impl.jdbc.Util.generateCsSQLException(Unknown Source)
	at org.apache.derby.impl.jdbc.EmbedConnection.newSQLException(Unknown Source)
	at org.apache.derby.impl.jdbc.EmbedConnection.checkUserCredentials(Unknown Source)
	at org.apache.derby.impl.jdbc.EmbedConnection.<init>(Unknown Source)
	at org.apache.derby.jdbc.InternalDriver$1.run(Unknown Source)
	at org.apache.derby.jdbc.InternalDriver$1.run(Unknown Source)
	at java.security.AccessController.doPrivileged(Native Method)
	at org.apache.derby.jdbc.InternalDriver.getNewEmbedConnection(Unknown Source)
	at org.apache.derby.jdbc.InternalDriver.connect(Unknown Source)
	at org.apache.derby.jdbc.InternalDriver.connect(Unknown Source)
	at org.apache.derby.jdbc.EmbeddedDriver.connect(Unknown Source)
	at org.apache.derby.impl.drda.Database.makeConnection(Unknown Source)
	at org.apache.derby.impl.drda.DRDAConnThread.getConnFromDatabaseName(Unknown Source)
	at org.apache.derby.impl.drda.DRDAConnThread.verifyUserIdPassword(Unknown Source)
	at org.apache.derby.impl.drda.DRDAConnThread.parseSECCHK(Unknown Source)
	at org.apache.derby.impl.drda.DRDAConnThread.parseDRDAConnection(Unknown Source)
	at org.apache.derby.impl.drda.DRDAConnThread.processCommands(Unknown Source)
	at org.apache.derby.impl.drda.DRDAConnThread.run(Unknown Source)
============= end nested exception, level (1) ===========
Cleanup action completed
Mon May 25 17:12:31 CEST 2020 Thread[DRDAConnThread_2,5,main] (DATABASE = TrainityDB), (DRDAID = {2}), Connection authentication failure occurred.  Reason: Invalid authentication..
----------------------------------------------------------------
Mon May 25 17:14:33 CEST 2020: Shutting down Derby engine
----------------------------------------------------------------
Mon May 25 17:14:33 CEST 2020:
Shutting down instance a816c00e-0172-4c64-5584-ffffbbcdf971 on database directory C:\Users\Moritz Weibold\OneDrive - HTBLA Leonding\ITP\Projekt\Trainity\Projekt_Code\DB\TrainityDB with class loader sun.misc.Launcher$AppClassLoader@1d44bcfa 
